<?xml version="1.0"?>
<robot name="diff_drive_robot" xmlns:xacro="http://ros.org/wiki/xacro">

  <!-- Base Link -->
  <link name="base_link">
    <visual>
      <geometry>
        <box size="0.5 0.3 0.2"/>  <!-- Length, Width, Height -->
      </geometry>
      <material>
        <color rgba="0.0 0.5 1.0 1.0"/>  <!-- Blue color -->
      </material>
    </visual>
  </link>

  <!-- Left Wheel -->
  <link name="left_wheel">
    <visual>
      <geometry>
        <cylinder radius="0.05" length="0.02"/>
      </geometry>
      <material>
        <color rgba="0.0 0.0 0.0 1.0"/>  <!-- Black color -->
      </material>
    </visual>
  </link>

  <!-- Right Wheel -->
  <link name="right_wheel">
    <visual>
      <geometry>
        <cylinder radius="0.05" length="0.02"/>
      </geometry>
      <material>
        <color rgba="0.0 0.0 0.0 1.0"/>  <!-- Black color -->
      </material>
    </visual>
  </link>

  <!-- Joints -->
  <joint name="left_wheel_joint" type="continuous">
    <parent link="base_link"/>
    <child link="left_wheel"/>
    <origin xyz="-0.15 0.15 0"/>
    <axis xyz="0 1 0"/>
  </joint>

  <joint name="right_wheel_joint" type="continuous">
    <parent link="base_link"/>
    <child link="right_wheel"/>
    <origin xyz="0.15 0.15 0"/>
    <axis xyz="0 1 0"/>
  </joint>

</robot>
